<?xml version="1.0" ?>
<robot
  name="out">
  <link
    name="base_link">
    <inertial>
      <origin
        xyz="3.81830135287586E-07 0.000490233160051715 0.0680911726169037"
        rpy="0 0 0" />
      <mass
        value="0.0392655917096801" />
      <inertia
        ixx="9.43410382858083E-05"
        ixy="-1.44041094435164E-10"
        ixz="-5.32973135063326E-10"
        iyy="9.35104576671302E-05"
        iyz="-7.06820587107806E-07"
        izz="4.67523617248987E-06" />
    </inertial>
    <visual>
      <origin
        xyz="0 0 0"
        rpy="0 0 0" />
      <geometry>
        <mesh
          filename="/home/daniel/Desktop/robotPathPlanning/Python/out/meshes/base_link.STL" />
      </geometry>
      <material
        name="">
        <color
          rgba="0.792156862745098 0.819607843137255 0.933333333333333 1" />
      </material>
    </visual>
    <collision>
      <origin
        xyz="0 0 0"
        rpy="0 0 0" />
      <geometry>
        <mesh
          filename="/home/daniel/Desktop/robotPathPlanning/Python/out/meshes/base_link.STL" />
      </geometry>
    </collision>
  </link>
  <link
    name="l1">
    <inertial>
      <origin
        xyz="-0.0775363356468722 0.000422757078719242 0.0209719220698855"
        rpy="0 0 0" />
      <mass
        value="0.0481140132679658" />
      <inertia
        ixx="4.25376178264651E-06"
        ixy="9.89719233172601E-07"
        ixz="-3.66991350194768E-06"
        iyy="0.000166336706299027"
        iyz="6.6021107795002E-09"
        izz="0.000167508840406389" />
    </inertial>
    <visual>
      <origin
        xyz="0 0 0"
        rpy="0 0 0" />
      <geometry>
        <mesh
          filename="/home/daniel/Desktop/robotPathPlanning/Python/out/meshes/l1.STL" />
      </geometry>
      <material
        name="">
        <color
          rgba="0.847058823529412 0.847058823529412 0.847058823529412 1" />
      </material>
    </visual>
    <collision>
      <origin
        xyz="0 0 0"
        rpy="0 0 0" />
      <geometry>
        <mesh
          filename="/home/daniel/Desktop/robotPathPlanning/Python/out/meshes/l1.STL" />
      </geometry>
    </collision>
  </link>
  <joint
    name="j1"
    type="revolute">
    <origin
      xyz="0 0.00948960000093205 0.124300000000103"
      rpy="1.5707963267949 1.5707963267949 0" />
    <parent
      link="base_link" />
    <child
      link="l1" />
    <axis
      xyz="0 0 1" />
	<limit effort="300" lower="-2.96705972839" upper="2.96705972839" velocity="10"/>
  </joint>
  <link
    name="l2">
    <inertial>
      <origin
        xyz="-0.0775266421097145 0.00040698713081562 0.0209719226551794"
        rpy="0 0 0" />
      <mass
        value="0.048114013091611" />
      <inertia
        ixx="4.24702973489523E-06"
        ixy="1.05106797568013E-06"
        ixz="-3.67698119293867E-06"
        iyy="0.000166415860643582"
        iyz="1.81256684874256E-08"
        izz="0.000167581262863039" />
    </inertial>
    <visual>
      <origin
        xyz="0 0 0"
        rpy="0 0 0" />
      <geometry>
        <mesh
          filename="/home/daniel/Desktop/robotPathPlanning/Python/out/meshes/l2.STL" />
      </geometry>
      <material
        name="">
        <color
          rgba="0.847058823529412 0.847058823529412 0.847058823529412 1" />
      </material>
    </visual>
    <collision>
      <origin
        xyz="0 0 0"
        rpy="0 0 0" />
      <geometry>
        <mesh
          filename="/home/daniel/Desktop/robotPathPlanning/Python/out/meshes/l2.STL" />
      </geometry>
    </collision>
  </link>
  <joint
    name="j2"
    type="revolute">
    <origin
      xyz="-0.152400000000055 0.00948960000012492 0.0199895999994416"
      rpy="1.57079632677987 6.81298260196904E-18 4.58383439686871E-17" />
    <parent
      link="l1" />
    <child
      link="l2" />
    <axis
      xyz="0 0 1" />
	<limit effort="300" lower="-2.96705972839" upper="2.96705972839" velocity="10"/>
  </joint>
  <link
    name="l3">
    <inertial>
      <origin
        xyz="0.077526636321468 -0.000406452303621498 0.0209719515362998"
        rpy="0 0 0" />
      <mass
        value="0.0481140130743189" />
      <inertia
        ixx="4.24699051210553E-06"
        ixy="1.05330102905974E-06"
        ixz="3.67688985446539E-06"
        iyy="0.00016641680669748"
        iyz="-1.85466771433333E-08"
        izz="0.000167582176419347" />
    </inertial>
    <visual>
      <origin
        xyz="0 0 0"
        rpy="0 0 0" />
      <geometry>
        <mesh
          filename="/home/daniel/Desktop/robotPathPlanning/Python/out/meshes/l3.STL" />
      </geometry>
      <material
        name="">
        <color
          rgba="0.792156862745098 0.819607843137255 0.933333333333333 1" />
      </material>
    </visual>
    <collision>
      <origin
        xyz="0 0 0"
        rpy="0 0 0" />
      <geometry>
        <mesh
          filename="/home/daniel/Desktop/robotPathPlanning/Python/out/meshes/l3.STL" />
      </geometry>
    </collision>
  </link>
  <joint
    name="j3"
    type="revolute">
    <origin
      xyz="-0.152400000000286 0.00948960000089014 0.0199896000011297"
      rpy="-1.57079632680991 4.58383439548628E-17 3.14159265358979" />
    <parent
      link="l2" />
    <child
      link="l3" />
    <axis
      xyz="0 0 1" />
	<limit effort="300" lower="-2.96705972839" upper="2.96705972839" velocity="10"/>
  </joint>
  <link
    name="l4">
    <inertial>
      <origin
        xyz="-0.0186830493415796 -6.20813135235876E-05 0.022135458347231"
        rpy="0 0 0" />
      <mass
        value="0.0220182823322274" />
      <inertia
        ixx="1.98116592302733E-06"
        ixy="1.08305327617486E-08"
        ixz="-8.92033835283855E-07"
        iyy="8.70461098190497E-06"
        iyz="8.64734798578683E-09"
        izz="9.07949191695857E-06" />
    </inertial>
    <visual>
      <origin
        xyz="0 0 0"
        rpy="0 0 0" />
      <geometry>
        <mesh
          filename="/home/daniel/Desktop/robotPathPlanning/Python/out/meshes/l4.STL" />
      </geometry>
      <material
        name="">
        <color
          rgba="0.847058823529412 0.847058823529412 0.847058823529412 1" />
      </material>
    </visual>
    <collision>
      <origin
        xyz="0 0 0"
        rpy="0 0 0" />
      <geometry>
        <mesh
          filename="/home/daniel/Desktop/robotPathPlanning/Python/out/meshes/l4.STL" />
      </geometry>
    </collision>
  </link>
  <joint
    name="j4"
    type="revolute">
    <origin
      xyz="0.152399999999532 -0.00948959999811314 0.0199896000001312"
      rpy="1.5707963267949 9.27091432324333E-16 3.14159265358979" />
    <parent
      link="l3" />
    <child
      link="l4" />
    <axis
      xyz="0 0 1" />
	<limit effort="300" lower="-2.96705972839" upper="2.96705972839" velocity="10"/>
  </joint>
  <link
    name="l5">
    <inertial>
      <origin
        xyz="-0.0762000000004666 1.17961196366423E-16 0.0199896000000001"
        rpy="0 0 0" />
      <mass
        value="0.00263328296223896" />
      <inertia
        ixx="8.03151303482884E-08"
        ixy="8.94418173979679E-22"
        ixz="2.14569496371279E-22"
        iyy="1.31432419211271E-06"
        iyz="6.80873041709125E-25"
        izz="1.31432419211271E-06" />
    </inertial>
    <visual>
      <origin
        xyz="0 0 0"
        rpy="0 0 0" />
      <geometry>
        <mesh
          filename="/home/daniel/Desktop/robotPathPlanning/Python/out/meshes/l5.STL" />
      </geometry>
      <material
        name="">
        <color
          rgba="0.792156862745098 0.819607843137255 0.933333333333333 1" />
      </material>
    </visual>
    <collision>
      <origin
        xyz="0 0 0"
        rpy="0 0 0" />
      <geometry>
        <mesh
          filename="/home/daniel/Desktop/robotPathPlanning/Python/out/meshes/l5.STL" />
      </geometry>
    </collision>
  </link>
  <joint
    name="g5"
    type="fixed">
    <origin
      xyz="0 0 0"
      rpy="0 0 0" />
    <parent
      link="l4" />
    <child
      link="l5" />
    <axis
      xyz="0 0 0" />
  </joint>
</robot>